<?xml version="1.0" ?>
<!-- =================================================================================== -->
<!-- |    This document was autogenerated by xacro from mobile.urdf.xacro              | -->
<!-- |    EDITING THIS FILE BY HAND IS NOT RECOMMENDED                                 | -->
<!-- =================================================================================== -->
<robot name="mobile_bot">
  <material name="panda_white">
    <color rgba="1. 1. 1. 1."/>
  </material>
  <material name="dark_grey">
    <color rgba="0.2 0.2 0.2 1.0"/>
  </material>
  <material name="light_grey">
    <color rgba="0.4 0.4 0.4 1.0"/>
  </material>
  <material name="red">
    <color rgba="0.8 0.0 0.0 1.0"/>
  </material>
  <material name="white">
    <color rgba="0.9 0.9 0.9 1.0"/>
  </material>
  <material name="black">
    <color rgba="0.15 0.15 0.15 1.0"/>
  </material>
  <link name="chassis">
    <visual>
      <origin rpy="0 0 0" xyz="0 0 0"/>
      <geometry>
        <mesh filename="file:///home/junglator/pandora_ws/install/mobile_bot/share/mobile_bot/meshes/mobile_bot/chassis_o.obj"/>
      </geometry>
      <material name="dark_grey"/>
    </visual>
    <collision>
      <origin xyz="0 0 0"/>
      <geometry>
        <mesh filename="file:///home/junglator/pandora_ws/install/mobile_bot/share/mobile_bot/meshes/mobile_bot/chassis_o.obj"/>
      </geometry>
      <material name="dark_grey"/>
    </collision>
    <inertial>
      <origin rpy="0 0 0" xyz="0 0 0"/>
      <mass value="30.00"/>
      <!--calcuated on the basis of dimension-->
      <inertia ixx="1.7755" ixy="0.00" ixz="0.00" iyy="1.40" iyz="0.00" izz="2.825"/>
    </inertial>
  </link>
  <link name="left_front_wheel">
    <visual>
      <origin rpy="0 0 0" xyz="0 0 0"/>
      <geometry>
        <mesh filename="file:///home/junglator/pandora_ws/install/mobile_bot/share/mobile_bot/meshes/mobile_bot/Wheel_Left.obj" scale="0.1 0.1 0.1"/>
      </geometry>
      <material name="black"/>
    </visual>
    <collision>
      <origin rpy="0 0 0" xyz="0 0 0"/>
      <geometry>
        <mesh filename="file:///home/junglator/pandora_ws/install/mobile_bot/share/mobile_bot/meshes/mobile_bot/Wheel_Left.obj" scale="0.1 0.1 0.1"/>
      </geometry>
      <material name="black"/>
    </collision>
    <inertial>
      <origin rpy="0 0 0" xyz="0 0 0"/>
      <mass value="0.329"/>
      <inertia ixx="0.0000129" ixy="0.00" ixz="0.00" iyy="0.000086529" iyz="0.0" izz="0.000086529"/>
    </inertial>
  </link>
  <link name="left_rear_wheel">
    <visual>
      <origin rpy="0 0 0" xyz="0 0 0"/>
      <geometry>
        <mesh filename="file:///home/junglator/pandora_ws/install/mobile_bot/share/mobile_bot/meshes/mobile_bot/Wheel_Left.obj" scale="0.1 0.1 0.1"/>
      </geometry>
      <material name="black"/>
    </visual>
    <collision>
      <origin rpy="0 0 0" xyz="0 0 0"/>
      <geometry>
        <mesh filename="file:///home/junglator/pandora_ws/install/mobile_bot/share/mobile_bot/meshes/mobile_bot/Wheel_Left.obj" scale="0.1 0.1 0.1"/>
      </geometry>
      <material name="black"/>
    </collision>
    <inertial>
      <origin rpy="0 0 0" xyz="0 0 0"/>
      <mass value="0.329"/>
      <inertia ixx="0.0000129" ixy="0.00" ixz="0.00" iyy="0.000086529" iyz="0.0" izz="0.000086529"/>
    </inertial>
  </link>
  <link name="right_front_wheel">
    <visual>
      <origin rpy="0 0 0" xyz="0 0 0"/>
      <geometry>
        <mesh filename="file:///home/junglator/pandora_ws/install/mobile_bot/share/mobile_bot/meshes/mobile_bot/Wheel_Right.obj" scale="0.1 0.1 0.1"/>
      </geometry>
      <material name="black"/>
    </visual>
    <collision>
      <origin rpy="0 0 0" xyz="0 0 0"/>
      <geometry>
        <mesh filename="file:///home/junglator/pandora_ws/install/mobile_bot/share/mobile_bot/meshes/mobile_bot/Wheel_Right.obj" scale="0.1 0.1 0.1"/>
      </geometry>
      <material name="black"/>
    </collision>
    <inertial>
      <origin rpy="0 0 0" xyz="0 0 0"/>
      <mass value="0.329"/>
      <inertia ixx="0.0000129" ixy="0.00" ixz="0.00" iyy="0.000086529" iyz="0.0" izz="0.000086529"/>
    </inertial>
  </link>
  <link name="right_rear_wheel">
    <visual>
      <origin rpy="0 0 0" xyz="0 0 0"/>
      <geometry>
        <mesh filename="file:///home/junglator/pandora_ws/install/mobile_bot/share/mobile_bot/meshes/mobile_bot/Wheel_Right.obj" scale="0.1 0.1 0.1"/>
      </geometry>
      <material name="black"/>
    </visual>
    <collision>
      <origin rpy="0 0 0" xyz="0 0 0"/>
      <geometry>
        <mesh filename="file:///home/junglator/pandora_ws/install/mobile_bot/share/mobile_bot/meshes/mobile_bot/Wheel_Right.obj" scale="0.1 0.1 0.1"/>
      </geometry>
      <material name="black"/>
    </collision>
    <inertial>
      <origin rpy="0 0 0" xyz="0 0 0"/>
      <mass value="0.329"/>
      <inertia ixx="0.0000129" ixy="0.00" ixz="0.00" iyy="0.000086529" iyz="0.0" izz="0.000086529"/>
    </inertial>
  </link>
  <link name="camera_one">
    <visual>
      <origin rpy="0 0 0" xyz="0 0 0"/>
      <geometry>
        <mesh filename="file:///home/junglator/pandora_ws/install/mobile_bot/share/mobile_bot/meshes/mobile_bot/realsense.obj" scale="0.001 0.001 0.001"/>
      </geometry>
      <material name="light_grey"/>
    </visual>
    <collision>
      <origin rpy="0 0 0" xyz="0 0 0"/>
      <geometry>
        <mesh filename="file:///home/junglator/pandora_ws/install/mobile_bot/share/mobile_bot/meshes/mobile_bot/realsense.obj" scale="0.001 0.001 0.001"/>
      </geometry>
      <material name="light_grey"/>
    </collision>
    <inertial>
      <origin rpy="0 0 0" xyz="0 0 0"/>
      <mass value="0.057836"/>
      <inertia ixx="0.0000046258" ixy="0.00" ixz="0.00" iyy="0.000052583276" iyz="0.0" izz="0.000052583276"/>
    </inertial>
  </link>
  <!--##################### LASER Link ####################-->
  <link name="laser_link">
    <visual>
      <origin rpy="0 0 0" xyz="0 0 0"/>
      <geometry>
        <box size="0.001 0.001 0.001"/>
      </geometry>
    </visual>
  </link>
  <!--##################### IMU Link ####################-->
  <link name="imu_link">
    <inertial>
      <mass value="0.001"/>
      <origin rpy="0 0 0" xyz="0 0 0"/>
      <inertia ixx="1e-09" ixy="0.0" ixz="0.0" iyy="1e-09" iyz="0.0" izz="1e-09"/>
    </inertial>
  </link>
  <!--######################Battery#########################-->
  <link name="battery">
    <visual>
      <origin rpy="0 0 0" xyz="0 0 0"/>
      <geometry>
        <box size="0.001 0.001 0.001"/>
      </geometry>
    </visual>
  </link>
  <!--###################### JOINTS ########################-->
  <joint name="front_left_wheel_joint" type="continuous">
    <origin rpy="0 0 0" xyz="-0.273 0.2237 -0.12"/>
    <parent link="chassis"/>
    <child link="right_front_wheel"/>
    <axis xyz="-1 0 0 "/>
  </joint>
  <joint name="rear_left_wheel_joint" type="continuous">
    <origin rpy="0 0 0" xyz="-0.273 -0.2237 -0.12"/>
    <parent link="chassis"/>
    <child link="left_rear_wheel"/>
    <axis xyz="-1 0 0"/>
  </joint>
  <joint name="front_right_wheel_joint" type="continuous">
    <origin rpy="0 0 0" xyz="0.273 0.2237 -0.12"/>
    <parent link="chassis"/>
    <child link="left_front_wheel"/>
    <axis xyz="-1 0 0"/>
  </joint>
  <joint name="rear_right_wheel_joint" type="continuous">
    <origin rpy="0 0 0" xyz="0.273 -0.2237 -0.12"/>
    <parent link="chassis"/>
    <child link="right_rear_wheel"/>
    <axis xyz="-1 0 0"/>
  </joint>
  <joint name="camera_joint" type="fixed">
    <origin rpy="-1.5707963267948966 0 0" xyz="0.0 0.395 0.074"/>
    <parent link="chassis"/>
    <child link="camera_one"/>
    <axis xyz="1 0 0"/>
  </joint>
  <joint name="imu_joint" type="fixed">
    <parent link="chassis"/>
    <child link="imu_link"/>
    <origin rpy="0 0 0" xyz="0 0 0"/>
  </joint>
  <joint name="laser_link_joint" type="fixed">
    <parent link="camera_one"/>
    <child link="laser_link"/>
    <origin rpy="1.57 -1.57 0" xyz="0 0 0"/>
  </joint>
  <joint name="battery_joint" type="fixed">
    <parent link="chassis"/>
    <child link="battery"/>
    <origin rpy="0 0 0" xyz="0 0 0"/>
  </joint>
  <!--Drive wheel transmission-->
  <transmission name="front_left_wheel_transmission">
    <type>transmission_interface/SimpleTransmission</type>
    <joint name="front_left_wheel_joint">
      <hardwareInterface>hardware_interface/VelocityJointInterface</hardwareInterface>
    </joint>
    <actuator name="FrontLeftWheelActuator">
      <hardwareInterface>hardware_interface/VelocityJointInterface</hardwareInterface>
      <mechanicalReduction>3</mechanicalReduction>
    </actuator>
  </transmission>
  <transmission name="front_right_wheel_transmission">
    <type>transmission_interface/SimpleTransmission</type>
    <joint name="front_right_wheel_joint">
      <hardwareInterface>hardware_interface/VelocityJointInterface</hardwareInterface>
    </joint>
    <actuator name="FrontRightWheelActuator">
      <hardwareInterface>hardware_interface/VelocityJointInterface</hardwareInterface>
      <mechanicalReduction>3</mechanicalReduction>
    </actuator>
  </transmission>
  <transmission name="rear_left_wheel_transmission">
    <type>transmission_interface/SimpleTransmission</type>
    <joint name="rear_left_wheel_joint">
      <hardwareInterface>hardware_interface/VelocityJointInterface</hardwareInterface>
    </joint>
    <actuator name="ReartLeftWheelActuator">
      <hardwareInterface>hardware_interface/VelocityJointInterface</hardwareInterface>
      <mechanicalReduction>3</mechanicalReduction>
    </actuator>
  </transmission>
  <transmission name="rear_right_wheel_transmission">
    <type>transmission_interface/SimpleTransmission</type>
    <joint name="rear_right_wheel_joint">
      <hardwareInterface>hardware_interface/VelocityJointInterface</hardwareInterface>
    </joint>
    <actuator name="RearRightWheelActuator">
      <hardwareInterface>hardware_interface/VelocityJointInterface</hardwareInterface>
      <mechanicalReduction>3</mechanicalReduction>
    </actuator>
  </transmission>
  <!--########################## MOBILE BOT ################################-->
  <gazebo reference="chassis">
    <material>Gazebo/Grey</material>
  </gazebo>
  <gazebo reference="left_front_wheel">
    <material>Gazebo/Black</material>
  </gazebo>
  <gazebo reference="left_rear_wheel">
    <material>Gazebo/Black</material>
  </gazebo>
  <gazebo reference="right_front_wheel">
    <material>Gazebo/Black</material>
  </gazebo>
  <gazebo reference="right_rear_wheel">
    <material>Gazebo/Black</material>
  </gazebo>
  <gazebo reference="camera_one">
    <material>Gazebo/FlatBlack</material>
  </gazebo>
  <gazebo reference="chassis">
    <gravity>true</gravity>
  </gazebo>
  <!--IMU PLUGIN-->
  <gazebo reference="imu_link">
    <gravity>true</gravity>
    <sensor name="imu_sensor" type="imu">
      <plugin filename="libgazebo_ros_imu_sensor.so" name="imu_plugin">
        <ros>
          <namespace>/</namespace>
          <remapping>~/out:=imu</remapping>
        </ros>
        <initial_orientation_as_reference>false</initial_orientation_as_reference>
      </plugin>
      <always_on>true</always_on>
      <update_rate>100</update_rate>
      <visualize>true</visualize>
      <imu>
        <angular_velocity>
          <x>
            <noise type="gaussian">
              <mean>0.0</mean>
              <stddev>2e-4</stddev>
              <bias_mean>0.0000075</bias_mean>
              <bias_stddev>0.0000008</bias_stddev>
            </noise>
          </x>
          <y>
            <noise type="gaussian">
              <mean>0.0</mean>
              <stddev>2e-4</stddev>
              <bias_mean>0.0000075</bias_mean>
              <bias_stddev>0.0000008</bias_stddev>
            </noise>
          </y>
          <z>
            <noise type="gaussian">
              <mean>0.0</mean>
              <stddev>2e-4</stddev>
              <bias_mean>0.0000075</bias_mean>
              <bias_stddev>0.0000008</bias_stddev>
            </noise>
          </z>
        </angular_velocity>
        <linear_acceleration>
          <x>
            <noise type="gaussian">
              <mean>0.0</mean>
              <stddev>1.7e-2</stddev>
              <bias_mean>0.1</bias_mean>
              <bias_stddev>0.001</bias_stddev>
            </noise>
          </x>
          <y>
            <noise type="gaussian">
              <mean>0.0</mean>
              <stddev>1.7e-2</stddev>
              <bias_mean>0.1</bias_mean>
              <bias_stddev>0.001</bias_stddev>
            </noise>
          </y>
          <z>
            <noise type="gaussian">
              <mean>0.0</mean>
              <stddev>1.7e-2</stddev>
              <bias_mean>0.1</bias_mean>
              <bias_stddev>0.001</bias_stddev>
            </noise>
          </z>
        </linear_acceleration>
      </imu>
    </sensor>
  </gazebo>
  <!--CAMERA PLUGIN-->
    <gazebo reference="camera_one">
      <sensor type="depth" name="camera_one_rgb_camera">
        <visualize>true</visualize>
        <update_rate>30.0</update_rate>
        <camera name="cam_one_rgb_camera">
          <pose>0 0 0 0 -1.57 1.57</pose>
          <horizontal_fov>1.3962634</horizontal_fov>
          <image>
            <width>640</width>
            <height>480</height>
            <format>R8G8B8</format>
          </image>
          <clip>
            <near>0.05</near>
            <far>10.0</far>
          </clip>
        </camera>
        <plugin name="camera_one_controller" filename="libgazebo_ros_camera.so">
          <baseline>0.2</baseline>
          <alwaysOn>true</alwaysOn>
          <updateRate>0.0</updateRate>
          <frameName>camera_depth_frame</frameName>
          <pointCloudCutoff>0.5</pointCloudCutoff>
          <pointCloudCutoffMax>3.0</pointCloudCutoffMax>
          <hackBaseline>0.07</hackBaseline>
          <distortionK1>0.0</distortionK1>
          <distortionK2>0.0</distortionK2>
          <distortionK3>0.0</distortionK3>
          <distortionT1>0.0</distortionT1>
          <distortionT2>0.0</distortionT2>
          <CxPrime>0</CxPrime>
          <Cx>0</Cx>
          <Cy>0</Cy>
          <focalLength>0</focalLength>
          <hackBaseline>0</hackBaseline>
        </plugin>
      </sensor>
    </gazebo>
  <!--LASER PLUGIN-->
  <gazebo reference="laser_link">
    <sensor name="laser_scanner" type="ray">
      <pose>0 0 0 0 0 0</pose>
      <ray>
        <scan>
          <horizontal>
            <samples>181</samples>
            <resolution>1</resolution>
            <min_angle>-1.57080</min_angle>
            <max_angle>1.57080</max_angle>
          </horizontal>
        </scan>
        <range>
          <min>0.08</min>
          <max>10</max>
          <resolution>0.05</resolution>
        </range>
        <noise>
          <type>gaussian</type>
          <mean>0.0</mean>
          <stddev>0.01</stddev>
        </noise>
      </ray>
      <always_on>true</always_on>
      <update_rate>10</update_rate>
      <visualize>true</visualize>
      <plugin filename="libgazebo_ros_ray_sensor.so" name="laser_scanner">
        <ros>
          <namespace>/</namespace>
          <argument>--ros-args --remap ~/out:=laser</argument>
        </ros>
        <output_type>sensor_msgs/LaserScan</output_type>
        <frame_name>laser_link</frame_name>
      </plugin>
    </sensor>
  </gazebo>
  <!--MECANUM WHEEL PLUGIN-->
  <!--gazebo>
    <!instead of using plugins for every wheel; used planar plugin to move the mobile bot>
        <plugin name="mecanum_controller" filename="libgazebo_ros_planar_move.so"> 
            <ros>
              <argument>odom:=odom/unfiltered</argument>
            </ros>
            <command_topic>cmd_vel</command_topic>
            <odometry_topic>odom/unfiltered</odometry_topic>
            <odometry_frame>odom</odometry_frame>
            <odometryRate>20.0</odometryRate>
            <update_rate>100</update_rate>
            <publish_rate>10</publish_rate>
            <robot_base_frame>base_footprint</robot_base_frame>
            <publish_odom>true</publish_odom>
            <publish_odom_tf>false</publish_odom_tf>
        </plugin>
    </gazebo-->
  <gazebo>
    <plugin filename="libgazebo_ros_diff_drive.so" name="wheel_drive_controller">
      <!-- wheels -->
      <num_wheel_pairs>2</num_wheel_pairs>
      <left_joint>front_left_wheel_joint</left_joint>
      <left_joint>rear_left_wheel_joint</left_joint>
      <right_joint>front_right_wheel_joint</right_joint>
      <right_joint>rear_right_wheel_joint</right_joint>
      <!-- kinematics -->
      <wheel_separation>0.3</wheel_separation>
      <wheel_diameter>0.06</wheel_diameter>
      <max_wheel_torque>20.0</max_wheel_torque>
      <max_wheel_acceleration>10.0</max_wheel_acceleration>
      <!-- odometry  -->
      <odometry_source>world</odometry_source>
      <odometry_frame>odom</odometry_frame>
      <robot_base_frame>base_footprint</robot_base_frame>
      <!-- topic & re remappings -->
      <ros>
        <namespace>/</namespace>
        <argument>--ros-args --remap /cmd_vel:=cmd_vel</argument>
        <argument>--ros-args --remap /odom:=odom</argument>
      </ros>
      <publish_odom>true</publish_odom>
      <publish_odom_tf>true</publish_odom_tf>
      <update_rate>100.0</update_rate>
    </plugin>
  </gazebo>
  <gazebo reference="front_left_wheel">
    <mu1 value="1.0"/>
    <mu2 value="1.0"/>
    <kp value="10000000.0"/>
    <kd value="1.0"/>
    <fdir1 value="1 0 0"/>
  </gazebo>
  <gazebo reference="front_right_wheel">
    <mu1 value="1.0"/>
    <mu2 value="1.0"/>
    <kp value="10000000.0"/>
    <kd value="1.0"/>
    <fdir1 value="1 0 0"/>
  </gazebo>
  <gazebo reference="rear_left_wheel">
    <mu1 value="1.0"/>
    <mu2 value="1.0"/>
    <kp value="10000000.0"/>
    <kd value="1.0"/>
    <fdir1 value="1 0 0"/>
  </gazebo>
  <gazebo reference="rear_right_wheel">
    <mu1 value="1.0"/>
    <mu2 value="1.0"/>
    <kp value="10000000.0"/>
    <kd value="1.0"/>
    <fdir1 value="1 0 0"/>
  </gazebo>
  <!--Properties-->
  <!--Mobile bot control-->
  <ros2_control name="mobile_bot_system" type="system">
    <hardware>
      <plugin>gazebo_ros2_control/GazeboSystem</plugin>
    </hardware>
    <joint name="front_left_wheel_joint">
      <command_interface name="velocity">
        <param name="min">-10</param>
        <param name="max">10</param>
      </command_interface>
      <state_interface name="velocity"/>
      <state_interface name="position"/>
    </joint>
    <joint name="front_right_wheel_joint">
      <command_interface name="velocity">
        <param name="min">-10</param>
        <param name="max">10</param>
      </command_interface>
      <state_interface name="velocity"/>
      <state_interface name="position"/>
    </joint>
    <joint name="rear_left_wheel_joint">
      <command_interface name="velocity">
        <param name="min">-10</param>
        <param name="max">10</param>
      </command_interface>
      <state_interface name="velocity"/>
      <state_interface name="position"/>
    </joint>
    <joint name="rear_right_wheel_joint">
      <command_interface name="velocity">
        <param name="min">-10</param>
        <param name="max">10</param>
      </command_interface>
      <state_interface name="velocity"/>
      <state_interface name="position"/>
    </joint>
  </ros2_control>
  <!--Pulgin setup-->
  <gazebo>
    <plugin filename="libgazebo_ros2_control.so" name="gazebo_ros2_control">
      <parameters>/home/junglator/pandora_ws/install/mobile_bot/share/mobile_bot/config/mobile_bot_controller.yaml</parameters>
    </plugin>
  </gazebo>
  <!--########################################################################################-->
  <link name="base_footprint"/>
  <joint name="base_link_joint" type="fixed">
    <origin rpy="0 0 1.5707963267948966" xyz="0 0 0.15"/>
    <parent link="base_footprint"/>
    <child link="chassis"/>
    <axis xyz="0 0 0"/>
  </joint>
</robot>
